Python 3.5.2 (default, Nov 17 2016, 17:05:23) 
[GCC 5.4.0 20160609] on linux
Type "copyright", "credits" or "license()" for more information.
>>> 
========== RESTART: /home/seth/Documents/SelfTaughtP_pp057_Scope.py ==========
1
2
3
101
>>> 
========== RESTART: /home/seth/Documents/SelfTaughtP_pp057_Scope.py ==========
1
2
3
101
>>> 
========== RESTART: /home/seth/Documents/SelfTaughtP_pp057_Scope.py ==========
Type a number: 6
Type another: 4
1.5
>>> 
>>> 
========== RESTART: /home/seth/Documents/SelfTaughtP_pp057_Scope.py ==========
Type a number: 6
Type another: 0
Traceback (most recent call last):
  File "/home/seth/Documents/SelfTaughtP_pp057_Scope.py", line 7, in <module>
    print(a/b)
ZeroDivisionError: division by zero
>>> 
========== RESTART: /home/seth/Documents/SelfTaughtP_pp057_Scope.py ==========
Type a number: 4
Type another: 0
Traceback (most recent call last):
  File "/home/seth/Documents/SelfTaughtP_pp057_Scope.py", line 7, in <module>
    print(a/b) # if "b" is zero, the program breaks
ZeroDivisionError: division by zero
>>> 
========== RESTART: /home/seth/Documents/SelfTaughtP_pp057_Scope.py ==========
Type a number: 5
Type another: 4
1.25
Type a number: 5
Type another: 0
b cannot be zero
>>> 
========== RESTART: /home/seth/Documents/SelfTaughtP_pp057_Scope.py ==========
Type a number: Hundo
Type another: Million
Traceback (most recent call last):
  File "/home/seth/Documents/SelfTaughtP_pp057_Scope.py", line 14, in <module>
    a = int(a)
ValueError: invalid literal for int() with base 10: 'Hundo'
>>> 
========== RESTART: /home/seth/Documents/SelfTaughtP_pp057_Scope.py ==========
Type a number: 5
Type another: George
Invalid Input. Please replace user and try again.
>>> 
========== RESTART: /home/seth/Documents/SelfTaughtP_pp057_Scope.py ==========
Type a number: 6
Type another: 5
1.2
>>> 
========== RESTART: /home/seth/Documents/SelfTaughtP_pp057_Scope.py ==========
Type a number: 4
Type another: 5
0.8
Traceback (most recent call last):
  File "/home/seth/Documents/SelfTaughtP_pp057_Scope.py", line 37, in <module>
    10/0
ZeroDivisionError: division by zero

During handling of the above exception, another exception occurred:

Traceback (most recent call last):
  File "/home/seth/Documents/SelfTaughtP_pp057_Scope.py", line 40, in <module>
    print(c)
NameError: name 'c' is not defined
>>> 
=============================== RESTART: Shell ===============================
>>> clear
Traceback (most recent call last):
  File "<pyshell#1>", line 1, in <module>
    clear
NameError: name 'clear' is not defined
>>> Clear
Traceback (most recent call last):
  File "<pyshell#2>", line 1, in <module>
    Clear
NameError: name 'Clear' is not defined
>>> 
======= RESTART: /home/seth/Documents/SelfTaughtP_pp064_Docstrings.py =======
7
>>> 
